<?xml version="1.0"?>
<robot name="dummyRplidar">

  <material name="blue">
    <color rgba="0 0 0.8 1"/>
  </material>
  <material name="black">
    <color rgba="0 0 0 1"/>
  </material>
  <material name="white">
    <color rgba="1 1 1 1"/>
  </material>


  <!-- <xacro:property name="baseRadius" value="0.175" />
  <xacro:property name="baseHeight" value="0.2" />

  <xacro:property name="wheelRadius" value="0.1" />
  <xacro:property name="wheelThickness" value="0.035" /> -->


  <link name="base_link">
    <visual>
      <geometry>
        <cylinder length="0.6" radius="0.175"/>
      </geometry>
      <material name="blue"/>
      <!-- <origin rpy="0 0 0" xyz="0 0 0.33"/> -->
    </visual>
    <collision>
      <geometry>
        <cylinder length="0.6" radius="0.175"/>
      </geometry>
    </collision>
    <inertial>
      <!-- <mass value="10"/>
      <inertia ixx="0.3677" ixy="0.0" ixz="0.0" iyy="0.3766" iyz="0.0" izz="0.1531"/> -->
      <mass value="50"/>
      <inertia ixx="1.8385" ixy="0.0" ixz="0.0" iyy="1.8385" iyz="0.0" izz="0.7655"/>
    </inertial>
  </link>

  <link name="right_wheel">
    <visual>
      <origin rpy="0 0 0" xyz="0 0 0.0250"/>
      <geometry>
        <cylinder length="0.035" radius="0.1"/>
      </geometry>
      <material name="white"/>
    </visual>
    <collision>
        <origin rpy="0 0 0" xyz="0 0 0.0250"/>
      <geometry>
        <cylinder length="0.035" radius="0.1"/>
      </geometry>
    </collision>
    <inertial>
        <origin rpy="0 0 0" xyz="0 0 0.0250"/>
      <mass value="0.3"/>
      <inertia ixx="0.00078" ixy="0.0" ixz="0.0" iyy="0.00078" iyz="0.0" izz="0.0015"/>
    </inertial>
  </link>

  <joint name="base_to_right_wheel" type="continuous">
      <axis rpy="0 0 0" xyz="0 0 1"/>
      <parent link="base_link"/>
      <child link="right_wheel"/>
      <origin xyz="0 -0.175 -0.23" rpy="1.57075 0 0"/>
  </joint>

  <!-- This block provides the simulator (Gazebo) with information on a few additional
    physical properties. See http://gazebosim.org/tutorials/?tut=ros_urdf for more-->
    <gazebo reference="right_wheel">
      <mu1 value="100.0"/>
      <mu2 value="100.0"/>
      <kp value="10000000.0" />
      <kd value="1.0" />
      <material>Gazebo/Grey</material>
    </gazebo>

    <!-- This block connects the wheel joint to an actuator (motor), which informs both
    simulation and visualization of the robot -->
    <transmission name="right_wheel_trans">
      <type>transmission_interface/SimpleTransmission</type>
      <actuator name="right_wheel_motor">
        <mechanicalReduction>1</mechanicalReduction>
      </actuator>
      <joint name="base_to_right_wheel">
        <hardwareInterface>VelocityJointInterface</hardwareInterface>
      </joint>
    </transmission>

  <link name="left_wheel">
    <visual>
      <!-- <origin rpy="1.57075 0 0" xyz="0 0.175 0"/> -->
      <origin rpy="0 0 0" xyz="0 0 -0.0250"/>
      <geometry>
        <cylinder length="0.035" radius="0.1"/>
      </geometry>
      <material name="white"/>
      <!-- <origin rpy="0 0 0" xyz="0 0 0"/> -->
    </visual>
    <collision>
      <origin rpy="0 0 0" xyz="0 0 -0.0250"/>
      <geometry>
        <cylinder length="0.035" radius="0.1"/>
      </geometry>
    </collision>
    <inertial>
        <origin rpy="0 0 0" xyz="0 0 -0.0250"/>
      <mass value="0.3"/>
      <inertia ixx="0.00078" ixy="0.0" ixz="0.0" iyy="0.00078" iyz="0.0" izz="0.0015"/>
    </inertial>
  </link>

  <joint name="base_to_left_wheel" type="continuous">
      <axis rpy="0 0 0" xyz="0 0 1"/>
      <parent link="base_link"/>
      <child link="left_wheel"/>
      <origin xyz="0 0.175 -0.23" rpy="1.57075 0 0"/> <!-- 0.175+0.0250 = 0.1 -->
  </joint>

  <!-- This block provides the simulator (Gazebo) with information on a few additional
    physical properties. See http://gazebosim.org/tutorials/?tut=ros_urdf for more-->
    <gazebo reference="left_wheel">
      <mu1 value="100.0"/>
      <mu2 value="100.0"/>
      <kp value="10000000.0" />
      <kd value="1.0" />
      <material>Gazebo/Grey</material>
    </gazebo>

    <!-- This block connects the wheel joint to an actuator (motor), which informs both
    simulation and visualization of the robot -->
    <transmission name="left_wheel_trans">
      <type>transmission_interface/SimpleTransmission</type>
      <actuator name="left_wheel_motor">
        <mechanicalReduction>1</mechanicalReduction>
      </actuator>
      <joint name="base_to_left_wheel">
        <hardwareInterface>VelocityJointInterface</hardwareInterface>
      </joint>
    </transmission>


  <link name="caster_back">
    <visual>
      <origin rpy="0 0 0" xyz="0 0 0"/>
      <geometry>
        <cylinder length="0.02" radius="0.01"/>
      </geometry>
      <material name="white"/>
    </visual>
    <collision>
      <geometry>
        <cylinder length="0.02" radius="0.01"/>
      </geometry>
      <!-- <surface>
        <friction>
          <ode>
            <mu>0</mu>
            <mu2>0</mu2>
            <slip1>1.0</slip1>
            <slip2>1.0</slip2>
          </ode>
        </friction>
      </surface> -->
    </collision>
    <inertial>
      <mass value="0.05"/>
      <inertia ixx="0.000013" ixy="0.0" ixz="0.0" iyy="0.000013" iyz="0.0" izz="0.0000225"/>
    </inertial>
  </link>

  <joint name="base_to_caster_back" type="fixed">
    <parent link="base_link"/>
    <child link="caster_back"/>
    <origin xyz="-0.15 0 -0.3175" rpy="1.57075 0 0"/>
  </joint>

  <gazebo reference="base_to_caster_back">
    <!-- <mu1>0.0</mu1>
    <mu2>0.0</mu2>
    <kp>1.0</kp>
    <kd>100000.0</kd>
    <minDepth>0.001</minDepth>
    <maxVel>1.0</maxVel> -->
    <mu1 value="0.0"/>
    <mu2 value="0.0"/>
    <kp value="1.0" />
    <kd value="10000000.0" />
    <minDepth value="1"/>
    <maxVel value="1.0" />
    <material>Gazebo/Grey</material>
  </gazebo>

  <link name="caster_front">
    <visual>
      <origin rpy="0 0 0" xyz="0 0 0"/>
      <geometry>
        <cylinder length="0.02" radius="0.01"/>
      </geometry>
      <material name="white"/>
    </visual>
    <collision>
      <geometry>
        <cylinder length="0.02" radius="0.01"/>
      </geometry>
      <!-- <surface>
        <friction>
          <ode>
            <mu>0</mu>
            <mu2>0</mu2>
            <slip1>1.0</slip1>
            <slip2>1.0</slip2>
          </ode>
        </friction>
      </surface> -->
    </collision>
    <inertial>
      <mass value="0.05"/>
      <inertia ixx="0.000013" ixy="0.0" ixz="0.0" iyy="0.000013" iyz="0.0" izz="0.0000225"/>
    </inertial>
  </link>

  <joint name="base_to_caster_front" type="fixed">
    <parent link="base_link"/>
    <child link="caster_front"/>
    <origin xyz="0.15 0 -0.3175" rpy="1.57075 0 0"/>
  </joint>

  <gazebo reference="base_to_caster_back">
    <!-- <mu1>0.0</mu1>
    <mu2>0.0</mu2>
    <kp>1.0</kp>
    <kd>100000.0</kd>
    <minDepth>0.001</minDepth>
    <maxVel>1.0</maxVel> -->
    <mu1 value="0.0"/>
    <mu2 value="0.0"/>
    <kp value="1.0" />
    <kd value="10000000.0" />
    <minDepth value="1"/>
    <maxVel value="1.0" />
    <material>Gazebo/Grey</material>
  </gazebo>

  <gazebo>
    <plugin name="gazebo_ros_control" filename="libgazebo_ros_control.so">
      <robotNamespace>/</robotNamespace>
    </plugin>
  </gazebo>

</robot>
